nohup: ignoring input
/home/szq/database/pyforum/website/models/user.py:5: ExtDeprecationWarning: Importing flask.ext.login is deprecated, use flask_login instead.
  from flask.ext.login import AnonymousUserMixin, UserMixin
/home/szq/database/pyforum/website/http/paginate.py:4: ExtDeprecationWarning: Importing flask.ext.paginate is deprecated, use flask_paginate instead.
  from flask.ext.paginate import Pagination
 * Running on http://127.0.0.1:5000/ (Press CTRL+C to quit)
 * Restarting with stat
/home/szq/database/pyforum/website/models/user.py:5: ExtDeprecationWarning: Importing flask.ext.login is deprecated, use flask_login instead.
  from flask.ext.login import AnonymousUserMixin, UserMixin
/home/szq/database/pyforum/website/http/paginate.py:4: ExtDeprecationWarning: Importing flask.ext.paginate is deprecated, use flask_paginate instead.
  from flask.ext.paginate import Pagination
 * Debugger is active!
 * Debugger pin code: 669-680-513
No connection available in pool.
127.0.0.1 - - [01/Jan/2019 18:39:55] "GET / HTTP/1.1" 500 -
Traceback (most recent call last):
  File "/home/szq/.conda/envs/Python36/lib/python3.6/site-packages/flask/app.py", line 1994, in __call__
    return self.wsgi_app(environ, start_response)
  File "/home/szq/.conda/envs/Python36/lib/python3.6/site-packages/flask/app.py", line 1985, in wsgi_app
    response = self.handle_exception(e)
  File "/home/szq/.conda/envs/Python36/lib/python3.6/site-packages/flask/app.py", line 1540, in handle_exception
    reraise(exc_type, exc_value, tb)
  File "/home/szq/.conda/envs/Python36/lib/python3.6/site-packages/flask/_compat.py", line 33, in reraise
    raise value
  File "/home/szq/.conda/envs/Python36/lib/python3.6/site-packages/flask/app.py", line 1982, in wsgi_app
    response = self.full_dispatch_request()
  File "/home/szq/.conda/envs/Python36/lib/python3.6/site-packages/flask/app.py", line 1614, in full_dispatch_request
    rv = self.handle_user_exception(e)
  File "/home/szq/.conda/envs/Python36/lib/python3.6/site-packages/flask/app.py", line 1517, in handle_user_exception
    reraise(exc_type, exc_value, tb)
  File "/home/szq/.conda/envs/Python36/lib/python3.6/site-packages/flask/_compat.py", line 33, in reraise
    raise value
  File "/home/szq/.conda/envs/Python36/lib/python3.6/site-packages/flask/app.py", line 1610, in full_dispatch_request
    rv = self.preprocess_request()
  File "/home/szq/.conda/envs/Python36/lib/python3.6/site-packages/flask/app.py", line 1831, in preprocess_request
    rv = func()
  File "/home/szq/.conda/envs/Python36/lib/python3.6/site-packages/playhouse/flask_utils.py", line 171, in connect_db
    self.database.connect()
  File "/home/szq/.conda/envs/Python36/lib/python3.6/site-packages/peewee.py", line 3602, in connect
    self.initialize_connection(self._local.conn)
  File "/home/szq/.conda/envs/Python36/lib/python3.6/site-packages/peewee.py", line 3514, in __exit__
    reraise(new_type, new_type(*exc_args), traceback)
  File "/home/szq/.conda/envs/Python36/lib/python3.6/site-packages/peewee.py", line 134, in reraise
    raise value.with_traceback(tb)
  File "/home/szq/.conda/envs/Python36/lib/python3.6/site-packages/peewee.py", line 3600, in connect
    **self.connect_kwargs)
  File "/home/szq/.conda/envs/Python36/lib/python3.6/site-packages/playhouse/pool.py", line 134, in _connect
    conn = super(PooledDatabase, self)._connect(*args, **kwargs)
  File "/home/szq/.conda/envs/Python36/lib/python3.6/site-packages/peewee.py", line 4144, in _connect
    return mysql.connect(db=database, **conn_kwargs)
  File "/home/szq/.conda/envs/Python36/lib/python3.6/site-packages/pymysql/__init__.py", line 90, in Connect
    return Connection(*args, **kwargs)
  File "/home/szq/.conda/envs/Python36/lib/python3.6/site-packages/pymysql/connections.py", line 688, in __init__
    self.connect()
  File "/home/szq/.conda/envs/Python36/lib/python3.6/site-packages/pymysql/connections.py", line 906, in connect
    self._request_authentication()
  File "/home/szq/.conda/envs/Python36/lib/python3.6/site-packages/pymysql/connections.py", line 1114, in _request_authentication
    auth_packet = self._read_packet()
  File "/home/szq/.conda/envs/Python36/lib/python3.6/site-packages/pymysql/connections.py", line 981, in _read_packet
    packet.check_error()
  File "/home/szq/.conda/envs/Python36/lib/python3.6/site-packages/pymysql/connections.py", line 393, in check_error
    err.raise_mysql_exception(self._data)
  File "/home/szq/.conda/envs/Python36/lib/python3.6/site-packages/pymysql/err.py", line 107, in raise_mysql_exception
    raise errorclass(errno, errval)
peewee.InternalError: (1049, "Unknown database 'pyforum'")
127.0.0.1 - - [01/Jan/2019 18:39:56] "GET /?__debugger__=yes&cmd=resource&f=style.css HTTP/1.1" 200 -
127.0.0.1 - - [01/Jan/2019 18:39:56] "GET /?__debugger__=yes&cmd=resource&f=jquery.js HTTP/1.1" 200 -
127.0.0.1 - - [01/Jan/2019 18:39:56] "GET /?__debugger__=yes&cmd=resource&f=debugger.js HTTP/1.1" 200 -
127.0.0.1 - - [01/Jan/2019 18:39:57] "GET /?__debugger__=yes&cmd=resource&f=ubuntu.ttf HTTP/1.1" 200 -
127.0.0.1 - - [01/Jan/2019 18:39:57] "GET /?__debugger__=yes&cmd=resource&f=console.png HTTP/1.1" 200 -
